Workbook

Sheet Change Analysis
J1: Date | K1: Values | R1: Date | S1: Values
J2: 11th | K2: 11th | L2: 13th+14th | M2: 13th+14th | N2: 11th | O2: 13th+14th | R2: 11th | S2: 11th | T2: 13th+14th | U2: 13th+14th | V2: 11th | W2: 13th+14th
B3: Date | C3: Values | I3: Country | J3: Sum of Conversion | K3: Sum of Cost | L3: Sum of Conversion | M3: Sum of Cost | N3: CPA | O3: CPA | Q3: Labels | R3: Sum of Conversion | S3: Sum of Cost | T3: Sum of Conversion | U3: Sum of Cost | V3: CPA | W3: CPA
B4: 11th | C4: 11th | D4: 13th+14th | E4: 13th+14th | F4: 11th | G4: 13th+14th | I4: US | J4: 50 | K4: 7307.55 | L4: 29 | M4: 7205.58 | N4: =IFERROR(K4/J4,200) -> 146.151 | O4: =IFERROR(M4/L4,200) -> 248.46828 | Q4: Keyword - Preroll | R4: 20 | S4: 2048.33 | T4: 9 | U4: 3727.06 | V4: =IFERROR(S4/R4,200) -> 102.4165 | W4: =IFERROR(U4/T4,200) -> 414.11778
A5: JB/TJ | B5: Sum of Conversion | C5: Sum of Cost | D5: Sum of Conversion | E5: Sum of Cost | F5: CPA | G5: CPA | I5: CP | J5: 36 | K5: 2635.36 | L5: 19 | M5: 2723.59 | N5: =IFERROR(K5/J5,200) -> 73.204444 | O5: =IFERROR(M5/L5,200) -> 143.34684 | Q5: Remarketing | R5: 25 | S5: 3403.69 | T5: 15 | U5: 2210.84 | V5: =IFERROR(S5/R5,200) -> 136.1476 | W5: =IFERROR(U5/T5,200) -> 147.38933
A6: JB | B6: 21 | C6: 2966.34 | D6: 16 | E6: 4411.7 | F6: =C6/B6 -> 141.25429 | G6: =E6/D6 -> 275.73125 | I6: DE | J6: 5 | K6: 677.64 | L6: 7 | M6: 600 | N6: =IFERROR(K6/J6,200) -> 135.528 | O6: =IFERROR(M6/L6,200) -> 85.714286 | Q6: Native - Homepage | R6: 26 | S6: 2304.63 | T6: 8 | U6: 1638.84 | V6: =IFERROR(S6/R6,200) -> 88.639615 | W6: =IFERROR(U6/T6,200) -> 204.855
A7: OLD | B7: 46 | C7: 3260.79 | D7: 22 | E7: 3064.06 | F7: =C7/B7 -> 70.886739 | G7: =E7/D7 -> 139.27545 | I7: CA | J7: 13 | K7: 679.57 | L7: 2 | M7: 493.22 | N7: =IFERROR(K7/J7,200) -> 52.274615 | O7: =IFERROR(M7/L7,200) -> 246.61 | Q7: Native - Watch | R7: 8 | S7: 1749.65 | T7: 10 | U7: 1514.12 | V7: =IFERROR(S7/R7,200) -> 218.70625 | W7: =IFERROR(U7/T7,200) -> 151.412
A8: TJ | B8: 66 | C8: 9773.97 | D8: 44 | E8: 7391.41 | F8: =C8/B8 -> 148.09045 | G8: =E8/D8 -> 167.98659 | I8: PH | J8: 2 | K8: 559.49 | L8: 0 | M8: 497.03 | N8: =IFERROR(K8/J8,200) -> 279.745 | O8: =IFERROR(M8/L8,200) -> 200 | Q8: Hentai | R8: 21 | S8: 1647.23 | T8: 7 | U8: 1226.65 | V8: =IFERROR(S8/R8,200) -> 78.439524 | W8: =IFERROR(U8/T8,200) -> 175.23571
I9: OL | J9: 10 | K9: 625.42 | L9: 3 | M9: 340.47 | N9: =IFERROR(K9/J9,200) -> 62.542 | O9: =IFERROR(M9/L9,200) -> 113.49 | Q9: General - Pre-roll - T3 | R9: 2 | S9: 1453.71 | T9: 4 | U9: 1188.36 | V9: =IFERROR(S9/R9,200) -> 726.855 | W9: =IFERROR(U9/T9,200) -> 297.09
I10: MX | J10: 2 | K10: 412.48 | L10: 2 | M10: 370.01 | N10: =IFERROR(K10/J10,200) -> 206.24 | O10: =IFERROR(M10/L10,200) -> 185.005 | Q10: Global | R10: 12 | S10: 862.26 | T10: 10 | U10: 1210.58 | V10: =IFERROR(S10/R10,200) -> 71.855 | W10: =IFERROR(U10/T10,200) -> 121.058
I11: AU | J11: 4 | K11: 407.67 | L11: 6 | M11: 249.18 | N11: =IFERROR(K11/J11,200) -> 101.9175 | O11: =IFERROR(M11/L11,200) -> 41.53 | Q11: Native - Search | R11: 4 | S11: 661.37 | T11: 4 | U11: 575.53 | V11: =IFERROR(S11/R11,200) -> 165.3425 | W11: =IFERROR(U11/T11,200) -> 143.8825
I12: EG | J12: 0 | K12: 232.68 | L12: 0 | M12: 218.46 | N12: =IFERROR(K12/J12,200) -> 200 | O12: =IFERROR(M12/L12,200) -> 200 | Q12: General - Pre-roll | R12: 1 | S12: 503.02 | T12: 1 | U12: 437.52 | V12: =IFERROR(S12/R12,200) -> 503.02 | W12: =IFERROR(U12/T12,200) -> 437.52
I13: LA | J13: 0 | K13: 239.94 | L13: 1 | M13: 194.71 | N13: =IFERROR(K13/J13,200) -> 200 | O13: =IFERROR(M13/L13,200) -> 194.71 | Q13: Gay | R13: 3 | S13: 388.42 | T13: 3 | U13: 352.25 | V13: =IFERROR(S13/R13,200) -> 129.47333 | W13: =IFERROR(U13/T13,200) -> 117.41667
I14: MA | J14: 0 | K14: 214.18 | L14: 1 | M14: 196.23 | N14: =IFERROR(K14/J14,200) -> 200 | O14: =IFERROR(M14/L14,200) -> 196.23 | Q14: Trans | R14: 4 | S14: 370.97 | T14: 1 | U14: 221 | V14: =IFERROR(S14/R14,200) -> 92.7425 | W14: =IFERROR(U14/T14,200) -> 221
I15: UK | J15: 1 | K15: 195.28 | L15: 0 | M15: 194.88 | N15: =IFERROR(K15/J15,200) -> 195.28 | O15: =IFERROR(M15/L15,200) -> 200 | Q15: Shorties | R15: 2 | S15: 275.83 | T15: 7 | U15: 309.56 | V15: =IFERROR(S15/R15,200) -> 137.915 | W15: =IFERROR(U15/T15,200) -> 44.222857
I16: CO | J16: 1 | K16: 182.9 | L16: 0 | M16: 160.34 | N16: =IFERROR(K16/J16,200) -> 182.9 | O16: =IFERROR(M16/L16,200) -> 200 | Q16: General | R16: 3 | S16: 164.76 | T16: 0 | U16: 126.25 | V16: =IFERROR(S16/R16,200) -> 54.92 | W16: =IFERROR(U16/T16,200) -> 200
I17: PE | J17: 0 | K17: 181.05 | L17: 0 | M17: 154.39 | N17: =IFERROR(K17/J17,200) -> 200 | O17: =IFERROR(M17/L17,200) -> 200 | Q17: AI | R17: 1 | S17: 143.51 | T17: 3 | U17: 110.37 | V17: =IFERROR(S17/R17,200) -> 143.51 | W17: =IFERROR(U17/T17,200) -> 36.79
I18: AR | J18: 2 | K18: 150.74 | L18: 1 | M18: 124.45 | N18: =IFERROR(K18/J18,200) -> 75.37 | O18: =IFERROR(M18/L18,200) -> 124.45 | Q18: Indian | R18: 0 | S18: 17.9 | T18: 0 | U18: 13.77 | V18: =IFERROR(S18/R18,200) -> 200 | W18: =IFERROR(U18/T18,200) -> 200
I19: BR | J19: 0 | K19: 153.19 | L19: 0 | M19: 113.48 | N19: =IFERROR(K19/J19,200) -> 200 | O19: =IFERROR(M19/L19,200) -> 200 | Q19: Ocean | R19: 0 | S19: 3 | T19: 0 | U19: 2.73 | V19: =IFERROR(S19/R19,200) -> 200 | W19: =IFERROR(U19/T19,200) -> 200
I20: NL | J20: 0 | K20: 117.19 | L20: 1 | M20: 120.62 | N20: =IFERROR(K20/J20,200) -> 200 | O20: =IFERROR(M20/L20,200) -> 120.62 | Q20: Furry | R20: 1 | S20: 2.82 | T20: 0 | U20: 1.74 | V20: =IFERROR(S20/R20,200) -> 2.82 | W20: =IFERROR(U20/T20,200) -> 200
I21: EC | J21: 0 | K21: 122.03 | L21: 0 | M21: 95.9 | N21: =IFERROR(K21/J21,200) -> 200 | O21: =IFERROR(M21/L21,200) -> 200 | Q21: FinDom | S21: 0 | U21: 0 | V21: =IFERROR(S21/R21,200) -> 200 | W21: =IFERROR(U21/T21,200) -> 200
I22: SG | J22: 0 | K22: 114.87 | L22: 0 | M22: 94.58 | N22: =IFERROR(K22/J22,200) -> 200 | O22: =IFERROR(M22/L22,200) -> 200 | Q22: Missionary | S22: 0 | U22: 0 | V22: =IFERROR(S22/R22,200) -> 200 | W22: =IFERROR(U22/T22,200) -> 200
I23: ES | J23: 1 | K23: 109.65 | L23: 1 | M23: 89.55 | N23: =IFERROR(K23/J23,200) -> 109.65 | O23: =IFERROR(M23/L23,200) -> 89.55 | Q23: Erotica Interest | S23: 0 | U23: 0 | V23: =IFERROR(S23/R23,200) -> 200 | W23: =IFERROR(U23/T23,200) -> 200
I24: LK | J24: 0 | K24: 99.68 | L24: 0 | M24: 88.79 | N24: =IFERROR(K24/J24,200) -> 200 | O24: =IFERROR(M24/L24,200) -> 200 | Q24: Tests | S24: 0 | U24: 0 | V24: =IFERROR(S24/R24,200) -> 200 | W24: =IFERROR(U24/T24,200) -> 200
I25: UA | J25: 0 | K25: 75.02 | L25: 2 | M25: 75.41 | N25: =IFERROR(K25/J25,200) -> 200 | O25: =IFERROR(M25/L25,200) -> 37.705 | Q25: VR Intent | S25: 0 | U25: 0 | V25: =IFERROR(S25/R25,200) -> 200 | W25: =IFERROR(U25/T25,200) -> 200
I26: PO | J26: 1 | K26: 73.7 | L26: 0 | M26: 60.89 | N26: =IFERROR(K26/J26,200) -> 73.7 | O26: =IFERROR(M26/L26,200) -> 200 | Q26: Big Tits | S26: 0 | U26: 0 | V26: =IFERROR(S26/R26,200) -> 200 | W26: =IFERROR(U26/T26,200) -> 200
I27: AZ | J27: 1 | K27: 55.15 | L27: 1 | M27: 48.06 | N27: =IFERROR(K27/J27,200) -> 55.15 | O27: =IFERROR(M27/L27,200) -> 48.06 | Q27: VOD Hentai Intent | S27: 0 | U27: 0 | V27: =IFERROR(S27/R27,200) -> 200 | W27: =IFERROR(U27/T27,200) -> 200
I28: TN | J28: 0 | K28: 50.11 | L28: 0 | M28: 48.04 | N28: =IFERROR(K28/J28,200) -> 200 | O28: =IFERROR(M28/L28,200) -> 200 | Q28: Marvel | S28: 0 | U28: 0 | V28: =IFERROR(S28/R28,200) -> 200 | W28: =IFERROR(U28/T28,200) -> 200
I29: BO | J29: 0 | K29: 49.23 | L29: 0 | M29: 39.07 | N29: =IFERROR(K29/J29,200) -> 200 | O29: =IFERROR(M29/L29,200) -> 200 | Q29: JB-Testing | S29: 0 | U29: 0 | V29: =IFERROR(S29/R29,200) -> 200 | W29: =IFERROR(U29/T29,200) -> 200
I30: IN | J30: 0 | K30: 45.37 | L30: 0 | M30: 41.75 | N30: =IFERROR(K30/J30,200) -> 200 | O30: =IFERROR(M30/L30,200) -> 200 | Q30: Cowgirl | S30: 0 | U30: 0 | V30: =IFERROR(S30/R30,200) -> 200 | W30: =IFERROR(U30/T30,200) -> 200
I31: HN | J31: 0 | K31: 35.84 | L31: 0 | M31: 26.56 | N31: =IFERROR(K31/J31,200) -> 200 | O31: =IFERROR(M31/L31,200) -> 200 | Q31: Archive | S31: 0 | U31: 0 | V31: =IFERROR(S31/R31,200) -> 200 | W31: =IFERROR(U31/T31,200) -> 200
I32: SV | J32: 0 | K32: 34.21 | L32: 0 | M32: 25.88 | N32: =IFERROR(K32/J32,200) -> 200 | O32: =IFERROR(M32/L32,200) -> 200 | Q32: Bin | S32: 0 | U32: 0 | V32: =IFERROR(S32/R32,200) -> 200 | W32: =IFERROR(U32/T32,200) -> 200
... I34: ZA | J34: 0 | K34: 30.29 | L34: 1 | M34: 25.98 | N34: =IFERROR(K34/J34,200) -> 200 | O34: =IFERROR(M34/L34,200) -> 25.98 | Q34: Blowjob | S34: 0 | U34: 0 | V34: =IFERROR(S34/R34,200) -> 200 | W34: =IFERROR(U34/T34,200) -> 200
I35: NZ | J35: 1 | K35: 20.42 | L35: 2 | M35: 35.38 | N35: =IFERROR(K35/J35,200) -> 20.42 | O35: =IFERROR(M35/L35,200) -> 17.69
I36: T2 | J36: 1 | K36: 26.82 | L36: 1 | M36: 23.78 | N36: =IFERROR(K36/J36,200) -> 26.82 | O36: =IFERROR(M36/L36,200) -> 23.78 | Q36: Labels | R36: Keyword - Preroll
I37: JP | J37: 0 | K37: 21.3 | L37: 1 | M37: 29.28 | N37: =IFERROR(K37/J37,200) -> 200 | O37: =IFERROR(M37/L37,200) -> 29.28
I38: IT | J38: 1 | K38: 15.82 | L38: 0 | M38: 10.87 | N38: =IFERROR(K38/J38,200) -> 15.82 | O38: =IFERROR(M38/L38,200) -> 200 | R38: Date | S38: Values
I39: PY | J39: 1 | K39: 15.7 | L39: 0 | M39: 10.89 | N39: =IFERROR(K39/J39,200) -> 15.7 | O39: =IFERROR(M39/L39,200) -> 200 | R39: 11th | S39: 11th | T39: 13th+14th | U39: 13th+14th | V39: 11th | W39: 13th+14th
I40: PL | J40: 0 | K40: 0.27 | L40: 1 | M40: 9.34 | N40: =IFERROR(K40/J40,200) -> 200 | O40: =IFERROR(M40/L40,200) -> 9.34 | Q40: Campaign Name | R40: Sum of Conversion | S40: Sum of Cost | T40: Sum of Conversion | U40: Sum of Cost | V40: CPA | W40: CPA
I41: CL | J41: 0 | K41: 0.31 | L41: 0 | M41: 4.87 | N41: =IFERROR(K41/J41,200) -> 200 | O41: =IFERROR(M41/L41,200) -> 200 | Q41: US_EN_PREROLL_CPA_PH-RT_KEY-Missionary_AND_M_JB | R41: 1 | S41: 101.22 | T41: 5 | U41: 2129.47 | V41: =IFERROR(S41/R41,200) -> 101.22 | W41: =IFERROR(U41/T41,200) -> 425.894
...

Sheet Overall Analysis
F1: Labels | G1: Keyword - Preroll | K1: Labels | L1: Hentai | P1: Labels | Q1: Native - Watch | U1: Labels | V1: Native - Homepage | Z1: Labels | AA1: Native - Search | AE1: Labels | AF1: Gay | AJ1: Labels | AK1: Trans
A3: Row Labels | B3: Sum of Conversion | C3: Sum of Cost | F3: Row Labels | G3: Sum of Conversion | H3: Sum of Cost | K3: Campaign Name | L3: Sum of Conversion | M3: Sum of Cost | P3: Row Labels | Q3: Sum of Conversion | R3: Sum of Cost | U3: Row Labels | V3: Sum of Conversion | W3: Sum of Cost | Z3: Row Labels | AA3: Sum of Conversion | AB3: Sum of Cost | AE3: Row Labels | AF3: Sum of Conversion | AG3: Sum of Cost | AJ3: Row Labels | AK3: Sum of Conversion | AL3: Sum of Cost | AO3: Campaign Name | AP3: Labels | AQ3: Sum of Conversion | AR3: Sum of Cost
A4: Keyword - Preroll | B4: 254 | C4: 33304.19 | D4: =C4/B4 -> 131.11886 | F4: AU | G4: 2 | H4: 348.76 | I4: =H4/G4 -> 174.38 | K4: US_EN_NATIVE_CPM_PH_ALL-MOB_HENTAI_SEGMENT_ALL_TJ | L4: 31 | M4: 2475.55 | N4: =M4/L4 -> 79.856452 | P4: DE | Q4: 27 | R4: 2989.78 | S4: =R4/Q4 -> 110.73259 | U4: US | V4: 99 | W4: 12367.4 | X4: =W4/V4 -> 124.92323 | Z4: DE | AA4: 24 | AB4: 2990.22 | AC4: =AB4/AA4 -> 124.5925 | AE4: US | AF4: 40 | AG4: 5441.14 | AH4: =AG4/AF4 -> 136.0285 | AJ4: US | AK4: 25 | AL4: 3146.14 | AM4: =AL4/AK4 -> 125.8456 | AO4: PH_EN_PREROLL_CPM_PH_MOB_ALL-MOB_ALL_TJ | AP4: General - Pre-roll | AQ4: 4 | AR4: 2870.98
A5: Native - Homepage | B5: 214 | C5: 22926.6 | D5: =C5/B5 -> 107.13364 | F5: CP | G5: 155 | H5: 12801.01 | I5: =H5/G5 -> 82.587161 | K5: US_EN_PREROLL_CPA_ALL_KEY-Hentai-Cartoon_iOS_M_JB | L5: 20 | M5: 2396.11 | N5: =M5/L5 -> 119.8055 | P5: MX | Q5: 4 | R5: 1780.44 | S5: =R5/Q5 -> 445.11 | U5: OL | V5: 61 | W5: 4988.73 | X5: =W5/V5 -> 81.782459 | Z5: MX | AA5: 7 | AB5: 1780.63 | AC5: =AB5/AA5 -> 254.37571 | AE5: CA | AF5: 3 | AG5: 273.26 | AH5: =AG5/AF5 -> 91.086667 | AJ5: CP | AK5: 13 | AL5: 2065.37 | AM5: =AL5/AK5 -> 158.87462 | AO5: US_EN_PREROLL_CPA_ALL_Broad_AND_MF_JB | AP5: General - Pre-roll | AQ5: 1 | AR5: 471.67
A6: Hentai | B6: 219 | C6: 20489.91 | D6: =C6/B6 -> 93.561233 | F6: NZ | G6: 2 | H6: 271.92 | I6: =H6/G6 -> 135.96 | K6: US_EN_PREROLL_CPA_ALL_KEY-Hentai-Cartoon_AND_M_JB | L6: 11 | M6: 2299.9 | N6: =M6/L6 -> 209.08182 | P6: AR | Q6: 7 | R6: 1335.47 | S6: =R6/Q6 -> 190.78143 | U6: CA | V6: 23 | W6: 1838.67 | X6: =W6/V6 -> 79.942174 | Z6: PH | AA6: 1 | AB6: 869.04 | AC6: =AB6/AA6 -> 869.04 | AE6: AU | AF6: 1 | AG6: 82.89 | AH6: =AG6/AF6 -> 82.89 | AJ6: Grand Total | AK6: 38 | AL6: 5211.51 | AM6: =AL6/AK6 -> 137.145 | AO6: US_EN_PREROLL_CPA_ALL_Broad_DESK_MF_JB | AP6: General - Pre-roll | AQ6: 12 | AR6: 3227.23
A7: Native - Watch | B7: 133 | C7: 16043 | D7: =C7/B7 -> 120.62406 | F7: UK | G7: 0 | H7: 115.9 | I7: =H7/G7 -> #DIV/0! | K7: CA_EN_PREROLL_CPA_ALL_KEY-Hentai-Cartoon_DESK_M_JB | L7: 20 | M7: 1896.53 | N7: =M7/L7 -> 94.8265 | P7: CO | Q7: 4 | R7: 1091.84 | S7: =R7/Q7 -> 272.96 | U7: UK | V7: 7 | W7: 1422.93 | X7: =W7/V7 -> 203.27571 | Z7: EG | AA7: 0 | AB7: 361.71 | AC7: =AB7/AA7 -> #DIV/0! | AE7: Grand Total | AF7: 44 | AG7: 5797.29 | AH7: =AG7/AF7 -> 131.75659
A8: Global | B8: 142 | C8: 14571.96 | D8: =C8/B8 -> 102.61944 | F8: US | G8: 95 | H8: 19766.6 | I8: =H8/G8 -> 208.06947 | K8: CA_EN_PREROLL_CPA_ALL_KEY-Hentai-Cartoon_iOS_M_JB | L8: 14 | M8: 1804.2 | N8: =M8/L8 -> 128.87143 | P8: PH | Q8: 2 | R8: 869.07 | S8: =R8/Q8 -> 434.535 | U8: AU | V8: 18 | W8: 1376.19 | X8: =W8/V8 -> 76.455 | Z8: Grand Total | AA8: 32 | AB8: 6001.6 | AC8: =AB8/AA8 -> 187.55 | AH8: =AG8/AF8 -> #DIV/0!
A9: General - Pre-roll - T3 | B9: 41 | C9: 12438.07 | D9: =C9/B9 -> 303.36756 | F9: Grand Total | G9: 254 | H9: 33304.19 | K9: US_EN_PREROLL_CPA_ALL_KEY-Hentai-Cartoon_DESK_M_JB | L9: 13 | M9: 1681.39 | N9: =M9/L9 -> 129.33769 | P9: BR | Q9: 2 | R9: 868.85 | S9: =R9/Q9 -> 434.425 | U9: PH | V9: 3 | W9: 869.04 | X9: =W9/V9 -> 289.68
A10: Remarketing | B10: 70 | C10: 10142.54 | D10: =C10/B10 -> 144.89343 | K10: CA_EN_PREROLL_CPA_ALL_KEY-Hentai-Cartoon_AND_M_JB | L10: 13 | M10: 1068.28 | N10: =M10/L10 -> 82.175385 | P10: ES | Q10: 9 | R10: 856.24 | S10: =R10/Q10 -> 95.137778 | U10: NZ | V10: 3 | W10: 63.64 | X10: =W10/V10 -> 21.213333
A11: General - Pre-roll | B11: 17 | C11: 6569.88 | D11: =C11/B11 -> 386.46353 | F11: Labels | G11: Keyword - Preroll | K11: OLD_CPA_Hentai_NativeVideo_iOS_USA_SD | L11: 15 | M11: 909.68 | N11: =M11/L11 -> 60.645333 | P11: NL | Q11: 7 | R11: 727.52 | S11: =R11/Q11 -> 103.93143 | U11: Grand Total | V11: 214 | W11: 22926.6 | X11: =W11/V11 -> 107.13364
A12: Native - Search | B12: 32 | C12: 6001.6 | D12: =C12/B12 -> 187.55 | F12: Country | G12: US | K12: CPA - Hentai - Video-IS - Desktop - Canada | L12: 10 | M12: 835.61 | N12: =M12/L12 -> 83.561 | P12: MA | Q12: 2 | R12: 667.48 | S12: =R12/Q12 -> 333.74
A13: Gay | B13: 44 | C13: 5797.29 | D13: =C13/B13 -> 131.75659 | K13: CPA - Hentai - Video-IS - excl. iOS - Canada | L13: 8 | M13: 778.91 | N13: =M13/L13 -> 97.36375 | P13: UA | Q13: 14 | R13: 659.8 | S13: =R13/Q13 -> 47.128571
A14: Trans | B14: 38 | C14: 5211.51 | D14: =C14/B14 -> 137.145 | F14: Campaign Name | G14: Sum of Conversion | H14: Sum of Cost | K14: CPA - Hentai - Video-IS - excl. iOS - Aus | L14: 7 | M14: 625.13 | N14: =M14/L14 -> 89.304286 | P14: AU | Q14: 20 | R14: 632.61 | S14: =R14/Q14 -> 31.6305
A15: Shorties | B15: 52 | C15: 4442.21 | D15: =C15/B15 -> 85.427115 | F15: US_EN_PREROLL_CPA_PH-RT_KEY-Missionary_AND_M_JB | G15: 26 | H15: 5794.67 | I15: =H15/G15 -> 222.87192 | K15: OLD_CPA_Hentai_NativeVideo_excl.-iOS_USA_SD | L15: 8 | M15: 483.06 | N15: =M15/L15 -> 60.3825 | P15: PO | Q15: 21 | R15: 627.21 | S15: =R15/Q15 -> 29.867143
A16: AI | B16: 27 | C16: 1744.47 | D16: =C16/B16 -> 64.61 | F16: US_EN_PREROLL_CPA_ALL_KEY-Cumshot_AND_M_JB | G16: 7 | H16: 1983.37 | I16: =H16/G16 -> 283.33857 | K16: OLD_CPA_Hentai_NativeVideo_excl.-iOS_Canada_SD | L16: 5 | M16: 456.61 | N16: =M16/L16 -> 91.322 | P16: PE | Q16: 1 | R16: 556.22 | S16: =R16/Q16 -> 556.22
A17: General | B17: 18 | C17: 1450.91 | D17: =C17/B17 -> 80.606111 | F17: US_EN_PREROLL_CPA_ALL_KEY-Cowgirl_iOS_M_JB | G17: 9 | H17: 1906.98 | I17: =H17/G17 -> 211.88667 | K17: OLD_CPA_Hentai_300x250_excl.-iOS_USA_SD | L17: 6 | M17: 440.88 | N17: =M17/L17 -> 73.48 | P17: SG | Q17: 1 | R17: 443.59 | S17: =R17/Q17 -> 443.59
A18: Indian | B18: 6 | C18: 246.78 | D18: =C18/B18 -> 41.13 | F18: US_EN_PREROLL_CPA_ALL_KEY-Blonde_AND_M_JB | G18: 6 | H18: 1629.76 | I18: =H18/G18 -> 271.62667 | K18: CPA - Hentai - NativeVideo - iOS - Canada | L18: 1 | M18: 339.59 | N18: =M18/L18 -> 339.59 | P18: LK | Q18: 0 | R18: 365.8 | S18: =R18/Q18 -> #DIV/0!
A19: Furry | B19: 2 | C19: 46.87 | D19: =C19/B19 -> 23.435 | F19: US_EN_PREROLL_CPA_ALL_KEY-Cowgirl_DESK_M_JB | G19: 16 | H19: 1591.8 | I19: =H19/G19 -> 99.4875 | K19: CPA - Hentai - Video-IS - Desktop - USA | L19: 6 | M19: 288.16 | N19: =M19/L19 -> 48.026667 | P19: EG | Q19: 1 | R19: 361.6 | S19: =R19/Q19 -> 361.6
A20: Ocean | B20: 0 | C20: 43.31 | D20: =C20/B20 -> #DIV/0! | F20: US_EN_PREROLL_CPA_ALL_KEY-Cumshot_iOS_M_JB | G20: 0 | H20: 1129.73 | I20: =H20/G20 -> #DIV/0! | K20: CPA - Hentai - Video-IS - Desktop - UK | L20: 2 | M20: 165.41 | N20: =M20/L20 -> 82.705 | P20: EC | Q20: 1 | R20: 347.3 | S20: =R20/Q20 -> 347.3
A21: JB-Testing | B21: 0 | C21: 0.02 | D21: =C21/B21 -> #DIV/0! | F21: US_EN_PREROLL_CPA_ALL_KEY-Blonde_iOS_M_JB | G21: 4 | H21: 896.52 | I21: =H21/G21 -> 224.13 | K21: T2_EN_PREROLL_CPA_ALL_KEY-Hentai-Cartoon_AND_M_JB | L21: 5 | M21: 130.09 | N21: =M21/L21 -> 26.018 | P21: ZA | Q21: 4 | R21: 317.92 | S21: =R21/Q21 -> 79.48
A22: Archive | B22: 0 | C22: 0 | D22: =C22/B22 -> #DIV/0! | F22: US_EN_PREROLL_CPA_ALL_KEY-Blonde_DESK_M_JB | G22: 7 | H22: 869.13 | I22: =H22/G22 -> 124.16143 | K22: T2_EN_PREROLL_CPA_ALL_KEY-Hentai-Cartoon_iOS_M_JB | L22: 1 | M22: 122.16 | N22: =M22/L22 -> 122.16 | P22: GT | Q22: 3 | R22: 300.1 | S22: =R22/Q22 -> 100.03333
A23: Tests | B23: 0 | C23: 0 | D23: =C23/B23 -> #DIV/0! | F23: US_EN_PREROLL_CPA_ALL_KEY-INDIAN_ALL_M_JB | G23: 2 | H23: 764.22 | I23: =H23/G23 -> 382.11 | K23: OLD_CPA_Hentai_NativeVideo_iOS_Aus_SD | L23: 2 | M23: 113.27 | N23: =M23/L23 -> 56.635 | P23: JP | Q23: 3 | R23: 244.16 | S23: =R23/Q23 -> 81.386667
A24: Cowgirl | C24: 0 | D24: =C24/B24 -> #DIV/0! | F24: US_EN_PREROLL_CPA_ALL_KEY-Cumshot_DESK_M_JB | G24: 9 | H24: 693.57 | I24: =H24/G24 -> 77.063333 | K24: OLD_CPA_Hentai_NativeVideo_excl.-iOS_Aus_SD | L24: 3 | M24: 106.32 | N24: =M24/L24 -> 35.44 | P24: Grand Total | Q24: 133 | R24: 16043 | S24: =R24/Q24 -> 120.62406
A25: Marvel | C25: 0 | D25: =C25/B25 -> #DIV/0! | F25: US_EN_PREROLL_CPA_PH-RT_KEY-Missionary_iOS_M_JB | G25: 2 | H25: 485.6 | I25: =H25/G25 -> 242.8 | K25: T2_EN_PREROLL_CPA_ALL_KEY-Hentai-Cartoon_DESK_M_JB | L25: 2 | M25: 102.12 | N25: =M25/L25 -> 51.06
A26: Big Tits | C26: 0 | D26: =C26/B26 -> #DIV/0! | F26: US_EN_PREROLL_CPA_ALL_KEY-Missionary_DESK_M_JB | G26: 2 | H26: 478.45 | I26: =H26/G26 -> 239.225 | K26: CPA - Hentai - Video-IS - excl. iOS - OTH | L26: 1 | M26: 99.37 | N26: =M26/L26 -> 99.37 | P26: No USA? | Z26: No USA? | AE26: No USA?
A27: Bin | B27: 0 | C27: 0 | D27: =C27/B27 -> #DIV/0! | F27: US_EN_PREROLL_CPA_ALL_KEY-Cowgirl_AND_M_JB | G27: 2 | H27: 466.44 | I27: =H27/G27 -> 233.22 | K27: CPA - Hentai - Video-IS - iOS - OTH | L27: 0 | M27: 90.44 | N27: =M27/L27 -> #DIV/0!
A28: Threesome | C28: 0 | D28: =C28/B28 -> #DIV/0! | F28: US_EN_PREROLL_CPA_T8-PH-YP_KEY-Handjob_iOS_M_JB | G28: 1 | H28: 370.85 | I28: =H28/G28 -> 370.85 | K28: OLD_CPA_Hentai_NativeVideo_Desktop_Canada_SD | L28: 0 | M28: 83.24 | N28: =M28/L28 -> #DIV/0! | P28: Labels | Q28: Native - Watch
A29: Missionary | C29: 0 | D29: =C29/B29 -> #DIV/0! | F29: US_EN_PREROLL_CPA_T8-YP_KEY-Handjob_DESK_M_JB | G29: 0 | H29: 230.7 | I29: =H29/G29 -> #DIV/0! | K29: CPA - Hentai - Video-IS - excl. iOS - USA | L29: 4 | M29: 77.32 | N29: =M29/L29 -> 19.33
A30: FinDom | B30: 0 | C30: 0 | D30: =C30/B30 -> #DIV/0! | F30: US_EN_PREROLL_CPA_T8-PH-YP_KEY-Handjob_AND_M_JB | G30: 1 | H30: 186.98 | I30: =H30/G30 -> 186.98 | K30: CPA - Hentai - Video-IS - Desktop - OTH | L30: 2 | M30: 70.95 | N30: =M30/L30 -> 35.475 | P30: Row Labels | Q30: Sum of Conversion | R30: Sum of Cost
A31: VOD Hentai Intent | B31: 0 | C31: 0 | D31: =C31/B31 -> #DIV/0! | F31: US_EN_PREROLL_CPA_PH_KEY-Blowjob_AND_M_JB | G31: 0 | H31: 181.27 | I31: =H31/G31 -> #DIV/0! | K31: OLD_CPA_Hentai_300x250_iOS_Aus_SD | L31: 0 | M31: 62.39 | N31: =M31/L31 -> #DIV/0! | P31: MX_EN_NATIVE_CPM_PH_WATCH_ALL-MOB_ALL_TJ | Q31: 4 | R31: 1780.44
A32: Erotica Interest | B32: 0 | C32: 0 | D32: =C32/B32 -> #DIV/0! | F32: US_EN_PREROLL_CPA_PH_KEY-Blowjob_iOS_M_JB | G32: 1 | H32: 86.65 | I32: =H32/G32 -> 86.65 | K32: OLD_CPA_Hentai_300x250_excl.-iOS_Aus_SD | L32: 3 | M32: 60.42 | N32: =M32/L32 -> 20.14 | P32: MX | Q32: 4 | R32: 1780.44
A33: VR Intent | C33: 0 | D33: =C33/B33 -> #DIV/0! | F33: US_EN_PREROLL_CPA_PH_KEY-Blowjob_DESK_M_JB | G33: 0 | H33: 19.91 | I33: =H33/G33 -> #DIV/0! | K33: OLD_CPA_Hentai_NativeVideo_Desktop_Aus_SD | L33: 0 | M33: 49.67 | N33: =M33/L33 -> #DIV/0! | P33: Grand Total | Q33: 4 | R33: 1780.44
A34: Blowjob | C34: 0 | D34: =C34/B34 -> #DIV/0! | K34: OLD_CPA_Hentai_NativeVideo_excl.-iOS_UK_SD | L34: 1 | M34: 42.06 | N34: =M34/L34 -> 42.06
A35: Grand Total | B35: 1309 | C35: 161471.12 | K35: CPA - Hentai - NativeVideo - excl. iOS - UK | L35: 2 | M35: 37.96 | N35: =M35/L35 -> 18.98
K36: OLD_CPA_Hentai_300x250_Desktop_UK_SD | L36: 0 | M36: 31.77 | N36: =M36/L36 -> #DIV/0!
K37: CPA - Hentai - 300x250 - Desktop - UK | L37: 0 | M37: 31.6 | N37: =M37/L37 -> #DIV/0!
K38: CPA - Hentai - Video-IS - iOS - USA | L38: 2 | M38: 30.39 | N38: =M38/L38 -> 15.195
K39: OLD_CPA_Hentai_300x250_excl.-iOS_UK_SD | L39: 0 | M39: 26.59 | N39: =M39/L39 -> #DIV/0!
A40: Row Labels | B40: Sum of Conversion | C40: Sum of Cost | K40: OLD_CPA_Hentai_300x250_iOS_UK_SD | L40: 0 | M40: 25.96 | N40: =M40/L40 -> #DIV/0!
A41: JB | B41: 271 | C41: 43958.43 | D41: =C41/B41 -> 162.20823 | K41: OLD_CPA_Hentai_300x250_Desktop_NZ_SD | L41: 0 | M41: 23.27 | N41: =M41/L41 -> #DIV/0!
...

Sheet Nov Extract
A1: Campaign Status | B1: ID | C1: Campaign Name | D1: Content Rating | E1: Dimensions | F1: Ad Format | G1: Exchange | H1: Device | I1: Targeting | J1: Active Ads | K1: Paused Ads | L1: Unlimited Budget | M1: Custom Budget | N1: Impressions | O1: Clicks | P1: CTR | Q1: Conversion | R1: Cost | S1: eCPM | T1: eCPC | U1: eCPA | V1: Tracker | W1: Rules | X1: Autopilot | Y1: Plays | Z1: Skips | AA1: Finishes | AB1: Group | AC1: Country | AD1: Labels | AE1: JB/TJ
A2: RUNNING | B2: 1011737002 | C2: CPA - AI - Video-IS - Desktop - USA | D2: nsfw | E2: 0.67291667 | F2: In-Stream Video | G2: TJX | H2: desktop | I2: GEO,Frequency,BrowserLanguage,Segment | J2: 230 | K2: 0 | L2: Yes | M2: Unlimited | N2: 49512 | O2: 2730 | P2: 5.51381 | Q2: 7 | R2: 213.56 | S2: 4.313 | T2: 0.078 | U2: 30.508 | V2: 1 | W2: 0 | X2: Yes | Y2: 49511 | Z2: 39008 | AA2: 5936 | AB2: AI | AC2: =LEFT(C2,2) -> CP | AD2: =_xlfn.XLOOKUP(C2,Mapping!A:A,Mapping!D:D,0,0) -> AI | AE2: =IFERROR(IF(SEARCH("_TJ",C2)>0,"TJ",NA()),IFERROR(IF(SEARCH("_JB",C2)>0,"JB",NA()),"OLD")) -> OLD
A3: PAUSED | B3: 1011737052 | C3: CPA - AI - Video-IS - Android - USA - BROKEN | D3: nsfw | E3: 0.67291667 | F3: In-Stream Video | G3: TJX | H3: mobile | I3: GEO,Frequency,OS,BrowserLanguage,Segment | J3: 308 | K3: 0 | L3: Yes | M3: Unlimited | N3: 0 | O3: 0 | P3: 0 | R3: 0 | S3: 0 | T3: 0 | U3: 0 | V3: 1 | W3: 0 | X3: Yes | AB3: Bin | AC3: =LEFT(C3,2) -> CP | AD3: =_xlfn.XLOOKUP(C3,Mapping!A:A,Mapping!D:D,0,0) -> Bin | AE3: =IFERROR(IF(SEARCH("_TJ",C3)>0,"TJ",NA()),IFERROR(IF(SEARCH("_JB",C3)>0,"JB",NA()),"OLD")) -> OLD
A4: PAUSED | B4: 1011737062 | C4: CPA - AI - Video-IS - iOS - USA - BROKEN | D4: nsfw | E4: 0.67291667 | F4: In-Stream Video | G4: TJX | H4: mobile | I4: GEO,Frequency,OS,BrowserLanguage,Segment | J4: 308 | K4: 0 | L4: Yes | M4: Unlimited | N4: 0 | O4: 0 | P4: 0 | R4: 0 | S4: 0 | T4: 0 | U4: 0 | V4: 1 | W4: 0 | X4: Yes | AB4: Bin | AC4: =LEFT(C4,2) -> CP | AD4: =_xlfn.XLOOKUP(C4,Mapping!A:A,Mapping!D:D,0,0) -> Bin | AE4: =IFERROR(IF(SEARCH("_TJ",C4)>0,"TJ",NA()),IFERROR(IF(SEARCH("_JB",C4)>0,"JB",NA()),"OLD")) -> OLD
A5: RUNNING | B5: 1011737262 | C5: CPA - AI - Video-IS - Desktop - Aus | D5: nsfw | E5: 0.67291667 | F5: In-Stream Video | G5: TJX | H5: desktop | I5: GEO,Frequency,BrowserLanguage,Segment | J5: 215 | K5: 0 | L5: Yes | M5: Unlimited | N5: 5627 | O5: 312 | P5: 5.5447 | Q5: 0 | R5: 15.32 | S5: 2.723 | T5: 0.049 | U5: 0 | V5: 1 | W5: 0 | X5: Yes | Y5: 5627 | Z5: 4466 | AA5: 668 | AB5: AI | AC5: =LEFT(C5,2) -> CP | AD5: =_xlfn.XLOOKUP(C5,Mapping!A:A,Mapping!D:D,0,0) -> AI | AE5: =IFERROR(IF(SEARCH("_TJ",C5)>0,"TJ",NA()),IFERROR(IF(SEARCH("_JB",C5)>0,"JB",NA()),"OLD")) -> OLD
A6: RUNNING | B6: 1011737272 | C6: CPA - AI - Video-IS - iOS - Aus | D6: nsfw | E6: 0.67291667 | F6: In-Stream Video | G6: TJX | H6: mobile | I6: GEO,Frequency,OS,BrowserLanguage,Segment | J6: 638 | K6: 0 | L6: Yes | M6: Unlimited | N6: 11261 | O6: 518 | P6: 4.59995 | Q6: 1 | R6: 39.16 | S6: 3.477 | T6: 0.076 | U6: 39.158 | V6: 1 | W6: 0 | X6: Yes | Y6: 11261 | Z6: 9916 | AA6: 1073 | AB6: AI | AC6: =LEFT(C6,2) -> CP | AD6: =_xlfn.XLOOKUP(C6,Mapping!A:A,Mapping!D:D,0,0) -> AI | AE6: =IFERROR(IF(SEARCH("_TJ",C6)>0,"TJ",NA()),IFERROR(IF(SEARCH("_JB",C6)>0,"JB",NA()),"OLD")) -> OLD
A7: RUNNING | B7: 1011737322 | C7: CPA - AI - Video-IS - excl. iOS - Aus | D7: nsfw | E7: 0.67291667 | F7: In-Stream Video | G7: TJX | H7: mobile | I7: GEO,Frequency,OS,BrowserLanguage,Segment | J7: 638 | K7: 0 | L7: Yes | M7: Unlimited | N7: 11408 | O7: 538 | P7: 4.71598 | Q7: 1 | R7: 45.48 | S7: 3.987 | T7: 0.085 | U7: 45.485 | V7: 1 | W7: 0 | X7: Yes | Y7: 11408 | Z7: 9960 | AA7: 1131 | AB7: AI | AC7: =LEFT(C7,2) -> CP | AD7: =_xlfn.XLOOKUP(C7,Mapping!A:A,Mapping!D:D,0,0) -> AI | AE7: =IFERROR(IF(SEARCH("_TJ",C7)>0,"TJ",NA()),IFERROR(IF(SEARCH("_JB",C7)>0,"JB",NA()),"OLD")) -> OLD
A8: RUNNING | B8: 1011744802 | C8: CPA - AI - Video-IS - Desktop - Canada | D8: nsfw | E8: 0.67291667 | F8: In-Stream Video | G8: TJX | H8: desktop | I8: GEO,Frequency,BrowserLanguage,Segment | J8: 285 | K8: 0 | L8: Yes | M8: Unlimited | N8: 15510 | O8: 889 | P8: 5.73179 | Q8: 1 | R8: 69.8 | S8: 4.5 | T8: 0.079 | U8: 69.8 | V8: 1 | W8: 0 | X8: Yes | Y8: 15510 | Z8: 12253 | AA8: 1897 | AB8: AI | AC8: =LEFT(C8,2) -> CP | AD8: =_xlfn.XLOOKUP(C8,Mapping!A:A,Mapping!D:D,0,0) -> AI | AE8: =IFERROR(IF(SEARCH("_TJ",C8)>0,"TJ",NA()),IFERROR(IF(SEARCH("_JB",C8)>0,"JB",NA()),"OLD")) -> OLD
A9: PAUSED | B9: 1011744812 | C9: CPA - AI - Video-IS - iOS - Canada | D9: nsfw | E9: 0.67291667 | F9: In-Stream Video | G9: TJX | H9: mobile | I9: GEO,Frequency,OS,BrowserLanguage,Segment | J9: 539 | K9: 0 | L9: Yes | M9: Unlimited | N9: 0 | O9: 0 | P9: 0 | R9: 0 | S9: 0 | T9: 0 | U9: 0 | V9: 1 | W9: 0 | X9: Yes | AB9: Bin | AC9: =LEFT(C9,2) -> CP | AD9: =_xlfn.XLOOKUP(C9,Mapping!A:A,Mapping!D:D,0,0) -> Bin | AE9: =IFERROR(IF(SEARCH("_TJ",C9)>0,"TJ",NA()),IFERROR(IF(SEARCH("_JB",C9)>0,"JB",NA()),"OLD")) -> OLD
A10: PAUSED | B10: 1011744822 | C10: CPA - AI - Video-IS - excl. iOS - Canada | D10: nsfw | E10: 0.67291667 | F10: In-Stream Video | G10: TJX | H10: mobile | I10: GEO,Frequency,OS,BrowserLanguage,Segment | J10: 638 | K10: 0 | L10: Yes | M10: Unlimited | N10: 0 | O10: 0 | P10: 0 | R10: 0 | S10: 0 | T10: 0 | U10: 0 | V10: 1 | W10: 0 | X10: Yes | AB10: AI | AC10: =LEFT(C10,2) -> CP | AD10: =_xlfn.XLOOKUP(C10,Mapping!A:A,Mapping!D:D,0,0) -> AI | AE10: =IFERROR(IF(SEARCH("_TJ",C10)>0,"TJ",NA()),IFERROR(IF(SEARCH("_JB",C10)>0,"JB",NA()),"OLD")) -> OLD
A11: RUNNING | B11: 1011744832 | C11: CPA - AI - Video-IS - Desktop - UK | D11: nsfw | E11: 0.67291667 | F11: In-Stream Video | G11: TJX | H11: desktop | I11: GEO,Frequency,BrowserLanguage,Segment | J11: 215 | K11: 0 | L11: Yes | M11: Unlimited | N11: 2477 | O11: 113 | P11: 4.56196 | Q11: 0 | R11: 11.28 | S11: 4.555 | T11: 0.1 | U11: 0 | V11: 1 | W11: 0 | X11: Yes | Y11: 2477 | Z11: 1935 | AA11: 342 | AB11: AI | AC11: =LEFT(C11,2) -> CP | AD11: =_xlfn.XLOOKUP(C11,Mapping!A:A,Mapping!D:D,0,0) -> AI | AE11: =IFERROR(IF(SEARCH("_TJ",C11)>0,"TJ",NA()),IFERROR(IF(SEARCH("_JB",C11)>0,"JB",NA()),"OLD")) -> OLD
A12: PAUSED | B12: 1011744842 | C12: CPA - AI - Video-IS - iOS - UK | D12: nsfw | E12: 0.67291667 | F12: In-Stream Video | G12: TJX | H12: mobile | I12: GEO,Frequency,OS,BrowserLanguage,Segment | J12: 539 | K12: 0 | L12: Yes | M12: Unlimited | N12: 0 | O12: 0 | P12: 0 | R12: 0 | S12: 0 | T12: 0 | U12: 0 | V12: 1 | W12: 0 | X12: Yes | AB12: Bin | AC12: =LEFT(C12,2) -> CP | AD12: =_xlfn.XLOOKUP(C12,Mapping!A:A,Mapping!D:D,0,0) -> Bin | AE12: =IFERROR(IF(SEARCH("_TJ",C12)>0,"TJ",NA()),IFERROR(IF(SEARCH("_JB",C12)>0,"JB",NA()),"OLD")) -> OLD
A13: RUNNING | B13: 1011744852 | C13: CPA - AI - Video-IS - excl. iOS - UK | D13: nsfw | E13: 0.67291667 | F13: In-Stream Video | G13: TJX | H13: mobile | I13: GEO,Frequency,OS,BrowserLanguage,Segment | J13: 638 | K13: 0 | L13: Yes | M13: Unlimited | N13: 7148 | O13: 354 | P13: 4.95242 | Q13: 1 | R13: 29.31 | S13: 4.101 | T13: 0.083 | U13: 29.314 | V13: 1 | W13: 0 | X13: Yes | Y13: 7148 | Z13: 6451 | AA13: 512 | AB13: AI | AC13: =LEFT(C13,2) -> CP | AD13: =_xlfn.XLOOKUP(C13,Mapping!A:A,Mapping!D:D,0,0) -> AI | AE13: =IFERROR(IF(SEARCH("_TJ",C13)>0,"TJ",NA()),IFERROR(IF(SEARCH("_JB",C13)>0,"JB",NA()),"OLD")) -> OLD
A14: PAUSED | B14: 1011744862 | C14: CPA - AI - Video-IS - excl. iOS - Norway | D14: nsfw | E14: 0.67291667 | F14: In-Stream Video | G14: TJX | H14: mobile | I14: GEO,Frequency,OS,BrowserLanguage,Segment | J14: 539 | K14: 0 | L14: Yes | M14: Unlimited | N14: 0 | O14: 0 | P14: 0 | R14: 0 | S14: 0 | T14: 0 | U14: 0 | V14: 1 | W14: 0 | X14: Yes | AB14: Bin | AC14: =LEFT(C14,2) -> CP | AD14: =_xlfn.XLOOKUP(C14,Mapping!A:A,Mapping!D:D,0,0) -> Bin | AE14: =IFERROR(IF(SEARCH("_TJ",C14)>0,"TJ",NA()),IFERROR(IF(SEARCH("_JB",C14)>0,"JB",NA()),"OLD")) -> OLD
A15: PAUSED | B15: 1011744872 | C15: CPA - AI - Video-IS - iOS - Norway | D15: nsfw | E15: 0.67291667 | F15: In-Stream Video | G15: TJX | H15: mobile | I15: GEO,Frequency,OS,BrowserLanguage,Segment | J15: 539 | K15: 0 | L15: Yes | M15: Unlimited | N15: 0 | O15: 0 | P15: 0 | R15: 0 | S15: 0 | T15: 0 | U15: 0 | V15: 1 | W15: 0 | X15: Yes | AB15: Bin | AC15: =LEFT(C15,2) -> CP | AD15: =_xlfn.XLOOKUP(C15,Mapping!A:A,Mapping!D:D,0,0) -> Bin | AE15: =IFERROR(IF(SEARCH("_TJ",C15)>0,"TJ",NA()),IFERROR(IF(SEARCH("_JB",C15)>0,"JB",NA()),"OLD")) -> OLD
A16: PAUSED | B16: 1011744882 | C16: CPA - AI - Video-IS - Desktop - Norway | D16: nsfw | E16: 0.67291667 | F16: In-Stream Video | G16: TJX | H16: desktop | I16: GEO,Frequency,BrowserLanguage,Segment | J16: 240 | K16: 0 | L16: Yes | M16: Unlimited | N16: 0 | O16: 0 | P16: 0 | R16: 0 | S16: 0 | T16: 0 | U16: 0 | V16: 1 | W16: 0 | X16: Yes | AB16: Bin | AC16: =LEFT(C16,2) -> CP | AD16: =_xlfn.XLOOKUP(C16,Mapping!A:A,Mapping!D:D,0,0) -> Bin | AE16: =IFERROR(IF(SEARCH("_TJ",C16)>0,"TJ",NA()),IFERROR(IF(SEARCH("_JB",C16)>0,"JB",NA()),"OLD")) -> OLD
A17: PAUSED | B17: 1011813152 | C17: CPA - Trans - Video-IS - Android - USA | D17: nsfw | E17: 0.67291667 | F17: In-Stream Video | G17: TJX | H17: mobile | I17: GEO,Frequency,OS,BrowserLanguage | J17: 352 | K17: 0 | L17: Yes | M17: Unlimited | N17: 0 | O17: 0 | P17: 0 | R17: 0 | S17: 0 | T17: 0 | U17: 0 | V17: 1 | W17: 0 | X17: Yes | AB17: Bin | AC17: =LEFT(C17,2) -> CP | AD17: =_xlfn.XLOOKUP(C17,Mapping!A:A,Mapping!D:D,0,0) -> Bin | AE17: =IFERROR(IF(SEARCH("_TJ",C17)>0,"TJ",NA()),IFERROR(IF(SEARCH("_JB",C17)>0,"JB",NA()),"OLD")) -> OLD
A18: PAUSED | B18: 1011813182 | C18: CPA - Shorties - Android - USA | D18: nsfw | E18: 0.38611111 | F18: In-Stream Video | G18: TJX | H18: mobile | I18: GEO,Frequency,OS,BrowserLanguage | J18: 11 | K18: 0 | L18: Yes | M18: Unlimited | N18: 0 | O18: 0 | P18: 0 | R18: 0 | S18: 0 | T18: 0 | U18: 0 | V18: 1 | W18: 0 | X18: Yes | AB18: Shorties | AC18: =LEFT(C18,2) -> CP | AD18: =_xlfn.XLOOKUP(C18,Mapping!A:A,Mapping!D:D,0,0) -> Shorties | AE18: =IFERROR(IF(SEARCH("_TJ",C18)>0,"TJ",NA()),IFERROR(IF(SEARCH("_JB",C18)>0,"JB",NA()),"OLD")) -> OLD
A19: PAUSED | B19: 1011813292 | C19: CPA - VR - Video-IS - Android - USA | D19: nsfw | E19: 0.67291667 | F19: In-Stream Video | G19: TJX | H19: mobile | I19: GEO,Frequency,Keyword,OS,BrowserLanguage | J19: 117 | K19: 0 | L19: No | M19: 100 | N19: 0 | O19: 0 | P19: 0 | R19: 0 | S19: 0 | T19: 0 | U19: 0 | V19: 1 | W19: 0 | X19: Yes | AB19: Bin | AC19: =LEFT(C19,2) -> CP | AD19: =_xlfn.XLOOKUP(C19,Mapping!A:A,Mapping!D:D,0,0) -> Bin | AE19: =IFERROR(IF(SEARCH("_TJ",C19)>0,"TJ",NA()),IFERROR(IF(SEARCH("_JB",C19)>0,"JB",NA()),"OLD")) -> OLD
A20: PAUSED | B20: 1011813302 | C20: CPA - Furry - Video-IS - Android - USA - BROKEN | D20: nsfw | E20: 0.67291667 | F20: In-Stream Video | G20: TJX | H20: mobile | I20: GEO,Frequency,Keyword,OS,BrowserLanguage | J20: 308 | K20: 0 | L20: Yes | M20: Unlimited | N20: 0 | O20: 0 | P20: 0 | R20: 0 | S20: 0 | T20: 0 | U20: 0 | V20: 1 | W20: 0 | X20: Yes | AB20: Bin | AC20: =LEFT(C20,2) -> CP | AD20: =_xlfn.XLOOKUP(C20,Mapping!A:A,Mapping!D:D,0,0) -> Bin | AE20: =IFERROR(IF(SEARCH("_TJ",C20)>0,"TJ",NA()),IFERROR(IF(SEARCH("_JB",C20)>0,"JB",NA()),"OLD")) -> OLD
A21: PAUSED | B21: 1011813312 | C21: CPA - Cosplay - Video-IS - Android - USA | D21: nsfw | E21: 0.67291667 | F21: In-Stream Video | G21: TJX | H21: mobile | I21: GEO,Frequency,Keyword,OS,BrowserLanguage | J21: 658 | K21: 0 | L21: Yes | M21: Unlimited | N21: 0 | O21: 0 | P21: 0 | R21: 0 | S21: 0 | T21: 0 | U21: 0 | V21: 1 | W21: 0 | X21: Yes | AB21: Bin | AC21: =LEFT(C21,2) -> CP | AD21: =_xlfn.XLOOKUP(C21,Mapping!A:A,Mapping!D:D,0,0) -> Bin | AE21: =IFERROR(IF(SEARCH("_TJ",C21)>0,"TJ",NA()),IFERROR(IF(SEARCH("_JB",C21)>0,"JB",NA()),"OLD")) -> OLD
A22: PAUSED | B22: 1011813322 | C22: CPA - Massage - Video-IS - Android - USA | D22: nsfw | E22: 0.67291667 | F22: In-Stream Video | G22: TJX | H22: mobile | I22: GEO,Frequency,Keyword,OS,BrowserLanguage | J22: 64 | K22: 0 | L22: No | M22: 100 | N22: 0 | O22: 0 | P22: 0 | R22: 0 | S22: 0 | T22: 0 | U22: 0 | V22: 1 | W22: 0 | X22: Yes | AB22: Bin | AC22: =LEFT(C22,2) -> CP | AD22: =_xlfn.XLOOKUP(C22,Mapping!A:A,Mapping!D:D,0,0) -> Bin | AE22: =IFERROR(IF(SEARCH("_TJ",C22)>0,"TJ",NA()),IFERROR(IF(SEARCH("_JB",C22)>0,"JB",NA()),"OLD")) -> OLD
A23: PAUSED | B23: 1011813332 | C23: CPA - JOI - Video-IS - Android - USA | D23: nsfw | E23: 0.67291667 | F23: In-Stream Video | G23: TJX | H23: mobile | I23: GEO,Frequency,Keyword,OS,BrowserLanguage | J23: 80 | K23: 0 | L23: Yes | M23: Unlimited | N23: 0 | O23: 0 | P23: 0 | R23: 0 | S23: 0 | T23: 0 | U23: 0 | V23: 1 | W23: 0 | X23: Yes | AB23: Bin | AC23: =LEFT(C23,2) -> CP | AD23: =_xlfn.XLOOKUP(C23,Mapping!A:A,Mapping!D:D,0,0) -> Bin | AE23: =IFERROR(IF(SEARCH("_TJ",C23)>0,"TJ",NA()),IFERROR(IF(SEARCH("_JB",C23)>0,"JB",NA()),"OLD")) -> OLD
A24: PAUSED | B24: 1011813342 | C24: CPA - Japanese - Video-IS - Android - USA | D24: nsfw | E24: 0.67291667 | F24: In-Stream Video | G24: TJX | H24: mobile | I24: GEO,Frequency,Keyword,OS,BrowserLanguage | J24: 117 | K24: 0 | L24: No | M24: 100 | N24: 0 | O24: 0 | P24: 0 | R24: 0 | S24: 0 | T24: 0 | U24: 0 | V24: 1 | W24: 0 | X24: Yes | AB24: Bin | AC24: =LEFT(C24,2) -> CP | AD24: =_xlfn.XLOOKUP(C24,Mapping!A:A,Mapping!D:D,0,0) -> Bin | AE24: =IFERROR(IF(SEARCH("_TJ",C24)>0,"TJ",NA()),IFERROR(IF(SEARCH("_JB",C24)>0,"JB",NA()),"OLD")) -> OLD
A25: PAUSED | B25: 1011813352 | C25: CPA - AI - Video-IS - Desktop - Mexico | D25: nsfw | E25: 0.67291667 | F25: In-Stream Video | G25: TJX | H25: desktop | I25: GEO,Frequency,BrowserLanguage,Segment | J25: 215 | K25: 0 | L25: Yes | M25: Unlimited | N25: 0 | O25: 0 | P25: 0 | R25: 0 | S25: 0 | T25: 0 | U25: 0 | V25: 1 | W25: 0 | X25: Yes | AB25: Bin | AC25: =LEFT(C25,2) -> CP | AD25: =_xlfn.XLOOKUP(C25,Mapping!A:A,Mapping!D:D,0,0) -> Bin | AE25: =IFERROR(IF(SEARCH("_TJ",C25)>0,"TJ",NA()),IFERROR(IF(SEARCH("_JB",C25)>0,"JB",NA()),"OLD")) -> OLD
A26: PAUSED | B26: 1011813362 | C26: CPA - AI - Video-IS - iOS - Mexico | D26: nsfw | E26: 0.67291667 | F26: In-Stream Video | G26: TJX | H26: mobile | I26: GEO,Frequency,OS,BrowserLanguage,Segment | J26: 539 | K26: 0 | L26: Yes | M26: Unlimited | N26: 0 | O26: 0 | P26: 0 | R26: 0 | S26: 0 | T26: 0 | U26: 0 | V26: 1 | W26: 0 | X26: Yes | AB26: Bin | AC26: =LEFT(C26,2) -> CP | AD26: =_xlfn.XLOOKUP(C26,Mapping!A:A,Mapping!D:D,0,0) -> Bin | AE26: =IFERROR(IF(SEARCH("_TJ",C26)>0,"TJ",NA()),IFERROR(IF(SEARCH("_JB",C26)>0,"JB",NA()),"OLD")) -> OLD
A27: PAUSED | B27: 1011813372 | C27: CPA - AI - Video-IS - excl. iOS - Mexico | D27: nsfw | E27: 0.67291667 | F27: In-Stream Video | G27: TJX | H27: mobile | I27: GEO,Frequency,OS,BrowserLanguage,Segment | J27: 539 | K27: 0 | L27: Yes | M27: Unlimited | N27: 0 | O27: 0 | P27: 0 | R27: 0 | S27: 0 | T27: 0 | U27: 0 | V27: 1 | W27: 0 | X27: Yes | AB27: Bin | AC27: =LEFT(C27,2) -> CP | AD27: =_xlfn.XLOOKUP(C27,Mapping!A:A,Mapping!D:D,0,0) -> Bin | AE27: =IFERROR(IF(SEARCH("_TJ",C27)>0,"TJ",NA()),IFERROR(IF(SEARCH("_JB",C27)>0,"JB",NA()),"OLD")) -> OLD
A28: RUNNING | B28: 1011813382 | C28: CPA - AI - Video-IS - excl. iOS - Italy | D28: nsfw | E28: 0.67291667 | F28: In-Stream Video | G28: TJX | H28: mobile | I28: GEO,Frequency,OS,BrowserLanguage,Segment | J28: 539 | K28: 0 | L28: Yes | M28: Unlimited | N28: 1045 | O28: 83 | P28: 7.94258 | Q28: 0 | R28: 4.04 | S28: 3.869 | T28: 0.049 | U28: 0 | V28: 1 | W28: 0 | X28: Yes | Y28: 1045 | Z28: 899 | AA28: 107 | AB28: Bin | AC28: =LEFT(C28,2) -> CP | AD28: =_xlfn.XLOOKUP(C28,Mapping!A:A,Mapping!D:D,0,0) -> AI | AE28: =IFERROR(IF(SEARCH("_TJ",C28)>0,"TJ",NA()),IFERROR(IF(SEARCH("_JB",C28)>0,"JB",NA()),"OLD")) -> OLD
A29: RUNNING | B29: 1011813392 | C29: CPA - AI - Video-IS - iOS - Italy | D29: nsfw | E29: 0.67291667 | F29: In-Stream Video | G29: TJX | H29: mobile | I29: GEO,Frequency,OS,BrowserLanguage,Segment | J29: 539 | K29: 0 | L29: Yes | M29: Unlimited | N29: 812 | O29: 38 | P29: 4.6798 | Q29: 0 | R29: 3.24 | S29: 3.986 | T29: 0.085 | U29: 0 | V29: 1 | W29: 0 | X29: Yes | Y29: 812 | Z29: 708 | AA29: 77 | AB29: Bin | AC29: =LEFT(C29,2) -> CP | AD29: =_xlfn.XLOOKUP(C29,Mapping!A:A,Mapping!D:D,0,0) -> Keyword - Preroll | AE29: =IFERROR(IF(SEARCH("_TJ",C29)>0,"TJ",NA()),IFERROR(IF(SEARCH("_JB",C29)>0,"JB",NA()),"OLD")) -> OLD
A30: PAUSED | B30: 1011813402 | C30: CPA - AI - Video-IS - Desktop - Italy | D30: nsfw | E30: 0.67291667 | F30: In-Stream Video | G30: TJX | H30: desktop | I30: GEO,Frequency,BrowserLanguage,Segment | J30: 240 | K30: 0 | L30: Yes | M30: Unlimited | N30: 0 | O30: 0 | P30: 0 | R30: 0 | S30: 0 | T30: 0 | U30: 0 | V30: 1 | W30: 0 | X30: Yes | AB30: Bin | AC30: =LEFT(C30,2) -> CP | AD30: =_xlfn.XLOOKUP(C30,Mapping!A:A,Mapping!D:D,0,0) -> Bin | AE30: =IFERROR(IF(SEARCH("_TJ",C30)>0,"TJ",NA()),IFERROR(IF(SEARCH("_JB",C30)>0,"JB",NA()),"OLD")) -> OLD
A31: PAUSED | B31: 1011813412 | C31: CPA - AI - Video-IS - Desktop - Japan | D31: nsfw | E31: 0.67291667 | F31: In-Stream Video | G31: TJX | H31: desktop | I31: GEO,Frequency,BrowserLanguage,Segment | J31: 215 | K31: 0 | L31: Yes | M31: Unlimited | N31: 0 | O31: 0 | P31: 0 | R31: 0 | S31: 0 | T31: 0 | U31: 0 | V31: 1 | W31: 0 | X31: Yes | AB31: Bin | AC31: =LEFT(C31,2) -> CP | AD31: =_xlfn.XLOOKUP(C31,Mapping!A:A,Mapping!D:D,0,0) -> Bin | AE31: =IFERROR(IF(SEARCH("_TJ",C31)>0,"TJ",NA()),IFERROR(IF(SEARCH("_JB",C31)>0,"JB",NA()),"OLD")) -> OLD
A32: PAUSED | B32: 1011813422 | C32: CPA - AI - Video-IS - iOS - Japan | D32: nsfw | E32: 0.67291667 | F32: In-Stream Video | G32: TJX | H32: mobile | I32: GEO,Frequency,OS,BrowserLanguage,Segment | J32: 539 | K32: 0 | L32: Yes | M32: Unlimited | N32: 0 | O32: 0 | P32: 0 | R32: 0 | S32: 0 | T32: 0 | U32: 0 | V32: 1 | W32: 0 | X32: Yes | AB32: Bin | AC32: =LEFT(C32,2) -> CP | AD32: =_xlfn.XLOOKUP(C32,Mapping!A:A,Mapping!D:D,0,0) -> Bin | AE32: =IFERROR(IF(SEARCH("_TJ",C32)>0,"TJ",NA()),IFERROR(IF(SEARCH("_JB",C32)>0,"JB",NA()),"OLD")) -> OLD
A33: PAUSED | B33: 1011813432 | C33: CPA - AI - Video-IS - Android - Japan | D33: nsfw | E33: 0.67291667 | F33: In-Stream Video | G33: TJX | H33: mobile | I33: GEO,Frequency,OS,BrowserLanguage,Segment | J33: 539 | K33: 0 | L33: Yes | M33: Unlimited | N33: 0 | O33: 0 | P33: 0 | R33: 0 | S33: 0 | T33: 0 | U33: 0 | V33: 1 | W33: 0 | X33: Yes | AB33: Bin | AC33: =LEFT(C33,2) -> CP | AD33: =_xlfn.XLOOKUP(C33,Mapping!A:A,Mapping!D:D,0,0) -> Bin | AE33: =IFERROR(IF(SEARCH("_TJ",C33)>0,"TJ",NA()),IFERROR(IF(SEARCH("_JB",C33)>0,"JB",NA()),"OLD")) -> OLD
A34: PAUSED | B34: 1011822352 | C34: CPA - AI - Shorties - Android - USA | D34: nsfw | E34: 0.38611111 | F34: In-Stream Video | G34: TJX | H34: mobile | I34: GEO,Frequency,OS,BrowserLanguage,Segment | J34: 2 | K34: 0 | L34: Yes | M34: Unlimited | N34: 0 | O34: 0 | P34: 0 | R34: 0 | S34: 0 | T34: 0 | U34: 0 | V34: 1 | W34: 0 | X34: Yes | AB34: Bin | AC34: =LEFT(C34,2) -> CP | AD34: =_xlfn.XLOOKUP(C34,Mapping!A:A,Mapping!D:D,0,0) -> Bin | AE34: =IFERROR(IF(SEARCH("_TJ",C34)>0,"TJ",NA()),IFERROR(IF(SEARCH("_JB",C34)>0,"JB",NA()),"OLD")) -> OLD
A35: PAUSED | B35: 1011822362 | C35: CPA - AI - Shorties - iOS - USA | D35: nsfw | E35: 0.38611111 | F35: In-Stream Video | G35: TJX | H35: mobile | I35: GEO,Frequency,OS,BrowserLanguage,Segment | J35: 2 | K35: 0 | L35: Yes | M35: Unlimited | N35: 0 | O35: 0 | P35: 0 | R35: 0 | S35: 0 | T35: 0 | U35: 0 | V35: 1 | W35: 0 | X35: Yes | AB35: Bin | AC35: =LEFT(C35,2) -> CP | AD35: =_xlfn.XLOOKUP(C35,Mapping!A:A,Mapping!D:D,0,0) -> Bin | AE35: =IFERROR(IF(SEARCH("_TJ",C35)>0,"TJ",NA()),IFERROR(IF(SEARCH("_JB",C35)>0,"JB",NA()),"OLD")) -> OLD
A36: PAUSED | B36: 1011822372 | C36: CPA - AI - Shorties - iOS - Aus | D36: nsfw | E36: 0.38611111 | F36: In-Stream Video | G36: TJX | H36: mobile | I36: GEO,Frequency,OS,BrowserLanguage,Segment | J36: 2 | K36: 0 | L36: Yes | M36: Unlimited | N36: 0 | O36: 0 | P36: 0 | R36: 0 | S36: 0 | T36: 0 | U36: 0 | V36: 1 | W36: 0 | X36: Yes | AB36: Bin | AC36: =LEFT(C36,2) -> CP | AD36: =_xlfn.XLOOKUP(C36,Mapping!A:A,Mapping!D:D,0,0) -> Bin | AE36: =IFERROR(IF(SEARCH("_TJ",C36)>0,"TJ",NA()),IFERROR(IF(SEARCH("_JB",C36)>0,"JB",NA()),"OLD")) -> OLD
A37: PAUSED | B37: 1011822382 | C37: CPA - AI - Shorties - Android - Aus | D37: nsfw | E37: 0.38611111 | F37: In-Stream Video | G37: TJX | H37: mobile | I37: GEO,Frequency,OS,BrowserLanguage,Segment | J37: 2 | K37: 0 | L37: Yes | M37: Unlimited | N37: 0 | O37: 0 | P37: 0 | R37: 0 | S37: 0 | T37: 0 | U37: 0 | V37: 1 | W37: 0 | X37: Yes | AB37: Bin | AC37: =LEFT(C37,2) -> CP | AD37: =_xlfn.XLOOKUP(C37,Mapping!A:A,Mapping!D:D,0,0) -> Bin | AE37: =IFERROR(IF(SEARCH("_TJ",C37)>0,"TJ",NA()),IFERROR(IF(SEARCH("_JB",C37)>0,"JB",NA()),"OLD")) -> OLD
A38: PAUSED | B38: 1011822392 | C38: CPA - JOI - Video-IS - iOS - USA | D38: nsfw | E38: 0.67291667 | F38: In-Stream Video | G38: TJX | H38: mobile | I38: GEO,Frequency,Keyword,OS,BrowserLanguage | J38: 72 | K38: 0 | L38: No | M38: 100 | N38: 0 | O38: 0 | P38: 0 | R38: 0 | S38: 0 | T38: 0 | U38: 0 | V38: 1 | W38: 0 | X38: Yes | AB38: Bin | AC38: =LEFT(C38,2) -> CP | AD38: =_xlfn.XLOOKUP(C38,Mapping!A:A,Mapping!D:D,0,0) -> Bin | AE38: =IFERROR(IF(SEARCH("_TJ",C38)>0,"TJ",NA()),IFERROR(IF(SEARCH("_JB",C38)>0,"JB",NA()),"OLD")) -> OLD
A39: PAUSED | B39: 1011822412 | C39: CPA - JOI - Video-IS - Desktop - USA - BROKEN | D39: nsfw | E39: 0.67291667 | F39: In-Stream Video | G39: TJX | H39: desktop | I39: GEO,Frequency,Keyword,BrowserLanguage | J39: 140 | K39: 0 | L39: Yes | M39: Unlimited | N39: 0 | O39: 0 | P39: 0 | R39: 0 | S39: 0 | T39: 0 | U39: 0 | V39: 1 | W39: 0 | X39: Yes | AB39: Bin | AC39: =LEFT(C39,2) -> CP | AD39: =_xlfn.XLOOKUP(C39,Mapping!A:A,Mapping!D:D,0,0) -> Bin | AE39: =IFERROR(IF(SEARCH("_TJ",C39)>0,"TJ",NA()),IFERROR(IF(SEARCH("_JB",C39)>0,"JB",NA()),"OLD")) -> OLD
A40: PAUSED | B40: 1011822422 | C40: CPA - JOI - Video-IS - Android - Aus | D40: nsfw | E40: 0.67291667 | F40: In-Stream Video | G40: TJX | H40: mobile | I40: GEO,Frequency,Keyword,OS,BrowserLanguage | J40: 468 | K40: 0 | L40: Yes | M40: Unlimited | N40: 0 | O40: 0 | P40: 0 | R40: 0 | S40: 0 | T40: 0 | U40: 0 | V40: 1 | W40: 0 | X40: Yes | AB40: Bin | AC40: =LEFT(C40,2) -> CP | AD40: =_xlfn.XLOOKUP(C40,Mapping!A:A,Mapping!D:D,0,0) -> Bin | AE40: =IFERROR(IF(SEARCH("_TJ",C40)>0,"TJ",NA()),IFERROR(IF(SEARCH("_JB",C40)>0,"JB",NA()),"OLD")) -> OLD
...

Sheet Mapping
A1: Campaign Name | B1: Cost | C1: Group | D1: Mapping
A2: US_EN_PREROLL_CPM_PH_ALL_MOB_RETARGETING_ALL_TJ | B2: 8209.8 | C2: Remarketing | D2: Remarketing
A3: US_EN_NATIVE_CPM_PH_HOMEPAGE_iOS_ALL_TJ | B3: 6626.33 | C3: General | D3: Native - Homepage
A4: CPA - Global - Video-IS - excl. iOS - OTH5 | B4: 6028.95 | C4: Global | D4: Global
A5: US_EN_PREROLL_CPA_PH-RT_KEY-Missionary_AND_M_JB | B5: 5794.67 | C5: Missionary | D5: Keyword - Preroll
A6: US_EN_NATIVE_CPM_PH_HOMEPAGE_ALL-MOB_ALL_TJ | B6: 5741.07 | C6: General | D6: Native - Homepage
A7: CPA - Pokemon/Digimon - Video-IS - ALL - USA | B7: 4254.79 | C7: Tests | D7: Keyword - Preroll
A8: US_EN_PREROLL_CPA_ALL_SOURCE-Gay_DESK_M_JB | B8: 3294.01 | C8: Gay | D8: Gay
A9: US_EN_PREROLL_CPA_ALL_Broad_DESK_MF_JB | B9: 3227.23 | C9: Broad | D9: General - Pre-roll
A10: OLD_CPA_Batch-1_Native-Homepage_excl-iOS_USA_SD | B10: 3003.46 | C10: General | D10: Native - Homepage
A11: DE_EN_NATIVE_CPM_PH_SEARCH_ALL_MOB_ALL_TJ | B11: 2990.22 | C11: General | D11: Native - Search
A12: DE_EN_NATIVE_CPM_PH_WATCH_ALL-MOB_ALL_TJ | B12: 2989.78 | C12: General | D12: Native - Watch
A13: PH_EN_PREROLL_CPM_PH_MOB_ALL-MOB_ALL_TJ | B13: 2870.98 | C13: General | D13: General - Pre-roll
... A1044: BR_EN_BANNER_CPM_PH_ALL_MOB_MIDDLE_ALL_TJ | B1044: 0 | C1044: General | D1044: General

Sheet Specific Extracts
A1: Date | B1: Campaign Status | C1: ID | D1: Campaign Name | E1: Content Rating | F1: Dimensions | G1: Ad Format | H1: Exchange | I1: Device | J1: Targeting | K1: Active Ads | L1: Paused Ads | M1: Unlimited Budget | N1: Custom Budget | O1: Impressions | P1: Clicks | Q1: CTR | R1: Conversion | S1: Cost | T1: eCPM | U1: eCPC | V1: eCPA | W1: Tracker | X1: Rules | Y1: Autopilot | Z1: Plays | AA1: Skips | AB1: Finishes | AC1: Group | AD1: Country | AE1: Labels | AF1: JB/TJ
A2: 13th+14th | B2: RUNNING | C2: 1011737002 | D2: CPA - AI - Video-IS - Desktop - USA | E2: nsfw | F2: 0.67291667 | G2: In-Stream Video | H2: TJX | I2: desktop | J2: GEO,Frequency,BrowserLanguage,Segment | K2: 230 | L2: 0 | M2: Yes | N2: Unlimited | O2: 3097 | P2: 149 | Q2: 4.81111 | R2: 0 | S2: 13.37 | T2: 4.316 | U2: 0.09 | V2: 0 | W2: 1 | X2: 0 | Y2: Yes | Z2: 3097 | AA2: 2421 | AB2: 391 | AC2: AI | AD2: =LEFT(D2,2) -> CP | AE2: =_xlfn.XLOOKUP(D2,Mapping!A:A,Mapping!D:D,0,0) -> AI | AF2: =IFERROR(IF(SEARCH("_TJ",D2)>0,"TJ",NA()),IFERROR(IF(SEARCH("_JB",D2)>0,"JB",NA()),"OLD")) -> OLD
A3: 13th+14th | B3: PAUSED | C3: 1011737052 | D3: CPA - AI - Video-IS - Android - USA - BROKEN | E3: nsfw | F3: 0.67291667 | G3: In-Stream Video | H3: TJX | I3: mobile | J3: GEO,Frequency,OS,BrowserLanguage,Segment | K3: 308 | L3: 0 | M3: Yes | N3: Unlimited | O3: 0 | P3: 0 | Q3: 0 | S3: 0 | T3: 0 | U3: 0 | V3: 0 | W3: 1 | X3: 0 | Y3: Yes | AC3: Bin | AD3: =LEFT(D3,2) -> CP | AE3: =_xlfn.XLOOKUP(D3,Mapping!A:A,Mapping!D:D,0,0) -> Bin | AF3: =IFERROR(IF(SEARCH("_TJ",D3)>0,"TJ",NA()),IFERROR(IF(SEARCH("_JB",D3)>0,"JB",NA()),"OLD")) -> OLD
A4: 13th+14th | B4: PAUSED | C4: 1011737062 | D4: CPA - AI - Video-IS - iOS - USA - BROKEN | E4: nsfw | F4: 0.67291667 | G4: In-Stream Video | H4: TJX | I4: mobile | J4: GEO,Frequency,OS,BrowserLanguage,Segment | K4: 308 | L4: 0 | M4: Yes | N4: Unlimited | O4: 0 | P4: 0 | Q4: 0 | S4: 0 | T4: 0 | U4: 0 | V4: 0 | W4: 1 | X4: 0 | Y4: Yes | AC4: Bin | AD4: =LEFT(D4,2) -> CP | AE4: =_xlfn.XLOOKUP(D4,Mapping!A:A,Mapping!D:D,0,0) -> Bin | AF4: =IFERROR(IF(SEARCH("_TJ",D4)>0,"TJ",NA()),IFERROR(IF(SEARCH("_JB",D4)>0,"JB",NA()),"OLD")) -> OLD
A5: 13th+14th | B5: RUNNING | C5: 1011737262 | D5: CPA - AI - Video-IS - Desktop - Aus | E5: nsfw | F5: 0.67291667 | G5: In-Stream Video | H5: TJX | I5: desktop | J5: GEO,Frequency,BrowserLanguage,Segment | K5: 215 | L5: 0 | M5: Yes | N5: Unlimited | O5: 404 | P5: 18 | Q5: 4.45545 | R5: 0 | S5: 1.1 | T5: 2.724 | U5: 0.061 | V5: 0 | W5: 1 | X5: 0 | Y5: Yes | Z5: 404 | AA5: 320 | AB5: 47 | AC5: AI | AD5: =LEFT(D5,2) -> CP | AE5: =_xlfn.XLOOKUP(D5,Mapping!A:A,Mapping!D:D,0,0) -> AI | AF5: =IFERROR(IF(SEARCH("_TJ",D5)>0,"TJ",NA()),IFERROR(IF(SEARCH("_JB",D5)>0,"JB",NA()),"OLD")) -> OLD
A6: 13th+14th | B6: RUNNING | C6: 1011737272 | D6: CPA - AI - Video-IS - iOS - Aus | E6: nsfw | F6: 0.67291667 | G6: In-Stream Video | H6: TJX | I6: mobile | J6: GEO,Frequency,OS,BrowserLanguage,Segment | K6: 638 | L6: 0 | M6: Yes | N6: Unlimited | O6: 813 | P6: 51 | Q6: 6.27306 | R6: 1 | S6: 2.84 | T6: 3.493 | U6: 0.056 | V6: 2.84 | W6: 1 | X6: 0 | Y6: Yes | Z6: 813 | AA6: 711 | AB6: 81 | AC6: AI | AD6: =LEFT(D6,2) -> CP | AE6: =_xlfn.XLOOKUP(D6,Mapping!A:A,Mapping!D:D,0,0) -> AI | AF6: =IFERROR(IF(SEARCH("_TJ",D6)>0,"TJ",NA()),IFERROR(IF(SEARCH("_JB",D6)>0,"JB",NA()),"OLD")) -> OLD
A7: 13th+14th | B7: RUNNING | C7: 1011737322 | D7: CPA - AI - Video-IS - excl. iOS - Aus | E7: nsfw | F7: 0.67291667 | G7: In-Stream Video | H7: TJX | I7: mobile | J7: GEO,Frequency,OS,BrowserLanguage,Segment | K7: 638 | L7: 0 | M7: Yes | N7: Unlimited | O7: 776 | P7: 28 | Q7: 3.60825 | R7: 0 | S7: 3.1 | T7: 3.996 | U7: 0.111 | V7: 0 | W7: 1 | X7: 0 | Y7: Yes | Z7: 776 | AA7: 669 | AB7: 91 | AC7: AI | AD7: =LEFT(D7,2) -> CP | AE7: =_xlfn.XLOOKUP(D7,Mapping!A:A,Mapping!D:D,0,0) -> AI | AF7: =IFERROR(IF(SEARCH("_TJ",D7)>0,"TJ",NA()),IFERROR(IF(SEARCH("_JB",D7)>0,"JB",NA()),"OLD")) -> OLD
A8: 13th+14th | B8: RUNNING | C8: 1011744802 | D8: CPA - AI - Video-IS - Desktop - Canada | E8: nsfw | F8: 0.67291667 | G8: In-Stream Video | H8: TJX | I8: desktop | J8: GEO,Frequency,BrowserLanguage,Segment | K8: 285 | L8: 0 | M8: Yes | N8: Unlimited | O8: 1208 | P8: 63 | Q8: 5.21523 | R8: 0 | S8: 5.43 | T8: 4.492 | U8: 0.086 | V8: 0 | W8: 1 | X8: 0 | Y8: Yes | Z8: 1208 | AA8: 948 | AB8: 155 | AC8: AI | AD8: =LEFT(D8,2) -> CP | AE8: =_xlfn.XLOOKUP(D8,Mapping!A:A,Mapping!D:D,0,0) -> AI | AF8: =IFERROR(IF(SEARCH("_TJ",D8)>0,"TJ",NA()),IFERROR(IF(SEARCH("_JB",D8)>0,"JB",NA()),"OLD")) -> OLD
A9: 13th+14th | B9: PAUSED | C9: 1011744812 | D9: CPA - AI - Video-IS - iOS - Canada | E9: nsfw | F9: 0.67291667 | G9: In-Stream Video | H9: TJX | I9: mobile | J9: GEO,Frequency,OS,BrowserLanguage,Segment | K9: 539 | L9: 0 | M9: Yes | N9: Unlimited | O9: 0 | P9: 0 | Q9: 0 | S9: 0 | T9: 0 | U9: 0 | V9: 0 | W9: 1 | X9: 0 | Y9: Yes | AC9: Bin | AD9: =LEFT(D9,2) -> CP | AE9: =_xlfn.XLOOKUP(D9,Mapping!A:A,Mapping!D:D,0,0) -> Bin | AF9: =IFERROR(IF(SEARCH("_TJ",D9)>0,"TJ",NA()),IFERROR(IF(SEARCH("_JB",D9)>0,"JB",NA()),"OLD")) -> OLD
A10: 13th+14th | B10: PAUSED | C10: 1011744822 | D10: CPA - AI - Video-IS - excl. iOS - Canada | E10: nsfw | F10: 0.67291667 | G10: In-Stream Video | H10: TJX | I10: mobile | J10: GEO,Frequency,OS,BrowserLanguage,Segment | K10: 638 | L10: 0 | M10: Yes | N10: Unlimited | O10: 0 | P10: 0 | Q10: 0 | S10: 0 | T10: 0 | U10: 0 | V10: 0 | W10: 1 | X10: 0 | Y10: Yes | AC10: AI | AD10: =LEFT(D10,2) -> CP | AE10: =_xlfn.XLOOKUP(D10,Mapping!A:A,Mapping!D:D,0,0) -> AI | AF10: =IFERROR(IF(SEARCH("_TJ",D10)>0,"TJ",NA()),IFERROR(IF(SEARCH("_JB",D10)>0,"JB",NA()),"OLD")) -> OLD
A11: 13th+14th | B11: RUNNING | C11: 1011744832 | D11: CPA - AI - Video-IS - Desktop - UK | E11: nsfw | F11: 0.67291667 | G11: In-Stream Video | H11: TJX | I11: desktop | J11: GEO,Frequency,BrowserLanguage,Segment | K11: 215 | L11: 0 | M11: Yes | N11: Unlimited | O11: 169 | P11: 9 | Q11: 5.32544 | R11: 0 | S11: 0.77 | T11: 4.556 | U11: 0.086 | V11: 0 | W11: 1 | X11: 0 | Y11: Yes | Z11: 169 | AA11: 138 | AB11: 22 | AC11: AI | AD11: =LEFT(D11,2) -> CP | AE11: =_xlfn.XLOOKUP(D11,Mapping!A:A,Mapping!D:D,0,0) -> AI | AF11: =IFERROR(IF(SEARCH("_TJ",D11)>0,"TJ",NA()),IFERROR(IF(SEARCH("_JB",D11)>0,"JB",NA()),"OLD")) -> OLD
A12: 13th+14th | B12: PAUSED | C12: 1011744842 | D12: CPA - AI - Video-IS - iOS - UK | E12: nsfw | F12: 0.67291667 | G12: In-Stream Video | H12: TJX | I12: mobile | J12: GEO,Frequency,OS,BrowserLanguage,Segment | K12: 539 | L12: 0 | M12: Yes | N12: Unlimited | O12: 0 | P12: 0 | Q12: 0 | S12: 0 | T12: 0 | U12: 0 | V12: 0 | W12: 1 | X12: 0 | Y12: Yes | AC12: Bin | AD12: =LEFT(D12,2) -> CP | AE12: =_xlfn.XLOOKUP(D12,Mapping!A:A,Mapping!D:D,0,0) -> Bin | AF12: =IFERROR(IF(SEARCH("_TJ",D12)>0,"TJ",NA()),IFERROR(IF(SEARCH("_JB",D12)>0,"JB",NA()),"OLD")) -> OLD
A13: 13th+14th | B13: RUNNING | C13: 1011744852 | D13: CPA - AI - Video-IS - excl. iOS - UK | E13: nsfw | F13: 0.67291667 | G13: In-Stream Video | H13: TJX | I13: mobile | J13: GEO,Frequency,OS,BrowserLanguage,Segment | K13: 638 | L13: 0 | M13: Yes | N13: Unlimited | O13: 495 | P13: 28 | Q13: 5.65657 | R13: 0 | S13: 2.03 | T13: 4.101 | U13: 0.072 | V13: 0 | W13: 1 | X13: 0 | Y13: Yes | Z13: 495 | AA13: 447 | AB13: 43 | AC13: AI | AD13: =LEFT(D13,2) -> CP | AE13: =_xlfn.XLOOKUP(D13,Mapping!A:A,Mapping!D:D,0,0) -> AI | AF13: =IFERROR(IF(SEARCH("_TJ",D13)>0,"TJ",NA()),IFERROR(IF(SEARCH("_JB",D13)>0,"JB",NA()),"OLD")) -> OLD
A14: 13th+14th | B14: PAUSED | C14: 1011744862 | D14: CPA - AI - Video-IS - excl. iOS - Norway | E14: nsfw | F14: 0.67291667 | G14: In-Stream Video | H14: TJX | I14: mobile | J14: GEO,Frequency,OS,BrowserLanguage,Segment | K14: 539 | L14: 0 | M14: Yes | N14: Unlimited | O14: 0 | P14: 0 | Q14: 0 | S14: 0 | T14: 0 | U14: 0 | V14: 0 | W14: 1 | X14: 0 | Y14: Yes | AC14: Bin | AD14: =LEFT(D14,2) -> CP | AE14: =_xlfn.XLOOKUP(D14,Mapping!A:A,Mapping!D:D,0,0) -> Bin | AF14: =IFERROR(IF(SEARCH("_TJ",D14)>0,"TJ",NA()),IFERROR(IF(SEARCH("_JB",D14)>0,"JB",NA()),"OLD")) -> OLD
A15: 13th+14th | B15: PAUSED | C15: 1011744872 | D15: CPA - AI - Video-IS - iOS - Norway | E15: nsfw | F15: 0.67291667 | G15: In-Stream Video | H15: TJX | I15: mobile | J15: GEO,Frequency,OS,BrowserLanguage,Segment | K15: 539 | L15: 0 | M15: Yes | N15: Unlimited | O15: 0 | P15: 0 | Q15: 0 | S15: 0 | T15: 0 | U15: 0 | V15: 0 | W15: 1 | X15: 0 | Y15: Yes | AC15: Bin | AD15: =LEFT(D15,2) -> CP | AE15: =_xlfn.XLOOKUP(D15,Mapping!A:A,Mapping!D:D,0,0) -> Bin | AF15: =IFERROR(IF(SEARCH("_TJ",D15)>0,"TJ",NA()),IFERROR(IF(SEARCH("_JB",D15)>0,"JB",NA()),"OLD")) -> OLD
A16: 13th+14th | B16: PAUSED | C16: 1011744882 | D16: CPA - AI - Video-IS - Desktop - Norway | E16: nsfw | F16: 0.67291667 | G16: In-Stream Video | H16: TJX | I16: desktop | J16: GEO,Frequency,BrowserLanguage,Segment | K16: 240 | L16: 0 | M16: Yes | N16: Unlimited | O16: 0 | P16: 0 | Q16: 0 | S16: 0 | T16: 0 | U16: 0 | V16: 0 | W16: 1 | X16: 0 | Y16: Yes | AC16: Bin | AD16: =LEFT(D16,2) -> CP | AE16: =_xlfn.XLOOKUP(D16,Mapping!A:A,Mapping!D:D,0,0) -> Bin | AF16: =IFERROR(IF(SEARCH("_TJ",D16)>0,"TJ",NA()),IFERROR(IF(SEARCH("_JB",D16)>0,"JB",NA()),"OLD")) -> OLD
A17: 13th+14th | B17: PAUSED | C17: 1011813152 | D17: CPA - Trans - Video-IS - Android - USA | E17: nsfw | F17: 0.67291667 | G17: In-Stream Video | H17: TJX | I17: mobile | J17: GEO,Frequency,OS,BrowserLanguage | K17: 352 | L17: 0 | M17: Yes | N17: Unlimited | O17: 0 | P17: 0 | Q17: 0 | S17: 0 | T17: 0 | U17: 0 | V17: 0 | W17: 1 | X17: 0 | Y17: Yes | AC17: Bin | AD17: =LEFT(D17,2) -> CP | AE17: =_xlfn.XLOOKUP(D17,Mapping!A:A,Mapping!D:D,0,0) -> Bin | AF17: =IFERROR(IF(SEARCH("_TJ",D17)>0,"TJ",NA()),IFERROR(IF(SEARCH("_JB",D17)>0,"JB",NA()),"OLD")) -> OLD
A18: 13th+14th | B18: PAUSED | C18: 1011813182 | D18: CPA - Shorties - Android - USA | E18: nsfw | F18: 0.38611111 | G18: In-Stream Video | H18: TJX | I18: mobile | J18: GEO,Frequency,OS,BrowserLanguage | K18: 11 | L18: 0 | M18: Yes | N18: Unlimited | O18: 0 | P18: 0 | Q18: 0 | S18: 0 | T18: 0 | U18: 0 | V18: 0 | W18: 1 | X18: 0 | Y18: Yes | AC18: Shorties | AD18: =LEFT(D18,2) -> CP | AE18: =_xlfn.XLOOKUP(D18,Mapping!A:A,Mapping!D:D,0,0) -> Shorties | AF18: =IFERROR(IF(SEARCH("_TJ",D18)>0,"TJ",NA()),IFERROR(IF(SEARCH("_JB",D18)>0,"JB",NA()),"OLD")) -> OLD
A19: 13th+14th | B19: PAUSED | C19: 1011813292 | D19: CPA - VR - Video-IS - Android - USA | E19: nsfw | F19: 0.67291667 | G19: In-Stream Video | H19: TJX | I19: mobile | J19: GEO,Frequency,Keyword,OS,BrowserLanguage | K19: 117 | L19: 0 | M19: No | N19: 100 | O19: 0 | P19: 0 | Q19: 0 | S19: 0 | T19: 0 | U19: 0 | V19: 0 | W19: 1 | X19: 0 | Y19: Yes | AC19: Bin | AD19: =LEFT(D19,2) -> CP | AE19: =_xlfn.XLOOKUP(D19,Mapping!A:A,Mapping!D:D,0,0) -> Bin | AF19: =IFERROR(IF(SEARCH("_TJ",D19)>0,"TJ",NA()),IFERROR(IF(SEARCH("_JB",D19)>0,"JB",NA()),"OLD")) -> OLD
A20: 13th+14th | B20: PAUSED | C20: 1011813302 | D20: CPA - Furry - Video-IS - Android - USA - BROKEN | E20: nsfw | F20: 0.67291667 | G20: In-Stream Video | H20: TJX | I20: mobile | J20: GEO,Frequency,Keyword,OS,BrowserLanguage | K20: 308 | L20: 0 | M20: Yes | N20: Unlimited | O20: 0 | P20: 0 | Q20: 0 | S20: 0 | T20: 0 | U20: 0 | V20: 0 | W20: 1 | X20: 0 | Y20: Yes | AC20: Bin | AD20: =LEFT(D20,2) -> CP | AE20: =_xlfn.XLOOKUP(D20,Mapping!A:A,Mapping!D:D,0,0) -> Bin | AF20: =IFERROR(IF(SEARCH("_TJ",D20)>0,"TJ",NA()),IFERROR(IF(SEARCH("_JB",D20)>0,"JB",NA()),"OLD")) -> OLD
A21: 13th+14th | B21: PAUSED | C21: 1011813312 | D21: CPA - Cosplay - Video-IS - Android - USA | E21: nsfw | F21: 0.67291667 | G21: In-Stream Video | H21: TJX | I21: mobile | J21: GEO,Frequency,Keyword,OS,BrowserLanguage | K21: 658 | L21: 0 | M21: Yes | N21: Unlimited | O21: 0 | P21: 0 | Q21: 0 | S21: 0 | T21: 0 | U21: 0 | V21: 0 | W21: 1 | X21: 0 | Y21: Yes | AC21: Bin | AD21: =LEFT(D21,2) -> CP | AE21: =_xlfn.XLOOKUP(D21,Mapping!A:A,Mapping!D:D,0,0) -> Bin | AF21: =IFERROR(IF(SEARCH("_TJ",D21)>0,"TJ",NA()),IFERROR(IF(SEARCH("_JB",D21)>0,"JB",NA()),"OLD")) -> OLD
A22: 13th+14th | B22: PAUSED | C22: 1011813322 | D22: CPA - Massage - Video-IS - Android - USA | E22: nsfw | F22: 0.67291667 | G22: In-Stream Video | H22: TJX | I22: mobile | J22: GEO,Frequency,Keyword,OS,BrowserLanguage | K22: 64 | L22: 0 | M22: No | N22: 100 | O22: 0 | P22: 0 | Q22: 0 | S22: 0 | T22: 0 | U22: 0 | V22: 0 | W22: 1 | X22: 0 | Y22: Yes | AC22: Bin | AD22: =LEFT(D22,2) -> CP | AE22: =_xlfn.XLOOKUP(D22,Mapping!A:A,Mapping!D:D,0,0) -> Bin | AF22: =IFERROR(IF(SEARCH("_TJ",D22)>0,"TJ",NA()),IFERROR(IF(SEARCH("_JB",D22)>0,"JB",NA()),"OLD")) -> OLD
A23: 13th+14th | B23: PAUSED | C23: 1011813332 | D23: CPA - JOI - Video-IS - Android - USA | E23: nsfw | F23: 0.67291667 | G23: In-Stream Video | H23: TJX | I23: mobile | J23: GEO,Frequency,Keyword,OS,BrowserLanguage | K23: 80 | L23: 0 | M23: Yes | N23: Unlimited | O23: 0 | P23: 0 | Q23: 0 | S23: 0 | T23: 0 | U23: 0 | V23: 0 | W23: 1 | X23: 0 | Y23: Yes | AC23: Bin | AD23: =LEFT(D23,2) -> CP | AE23: =_xlfn.XLOOKUP(D23,Mapping!A:A,Mapping!D:D,0,0) -> Bin | AF23: =IFERROR(IF(SEARCH("_TJ",D23)>0,"TJ",NA()),IFERROR(IF(SEARCH("_JB",D23)>0,"JB",NA()),"OLD")) -> OLD
A24: 13th+14th | B24: PAUSED | C24: 1011813342 | D24: CPA - Japanese - Video-IS - Android - USA | E24: nsfw | F24: 0.67291667 | G24: In-Stream Video | H24: TJX | I24: mobile | J24: GEO,Frequency,Keyword,OS,BrowserLanguage | K24: 117 | L24: 0 | M24: No | N24: 100 | O24: 0 | P24: 0 | Q24: 0 | S24: 0 | T24: 0 | U24: 0 | V24: 0 | W24: 1 | X24: 0 | Y24: Yes | AC24: Bin | AD24: =LEFT(D24,2) -> CP | AE24: =_xlfn.XLOOKUP(D24,Mapping!A:A,Mapping!D:D,0,0) -> Bin | AF24: =IFERROR(IF(SEARCH("_TJ",D24)>0,"TJ",NA()),IFERROR(IF(SEARCH("_JB",D24)>0,"JB",NA()),"OLD")) -> OLD
A25: 13th+14th | B25: PAUSED | C25: 1011813352 | D25: CPA - AI - Video-IS - Desktop - Mexico | E25: nsfw | F25: 0.67291667 | G25: In-Stream Video | H25: TJX | I25: desktop | J25: GEO,Frequency,BrowserLanguage,Segment | K25: 215 | L25: 0 | M25: Yes | N25: Unlimited | O25: 0 | P25: 0 | Q25: 0 | S25: 0 | T25: 0 | U25: 0 | V25: 0 | W25: 1 | X25: 0 | Y25: Yes | AC25: Bin | AD25: =LEFT(D25,2) -> CP | AE25: =_xlfn.XLOOKUP(D25,Mapping!A:A,Mapping!D:D,0,0) -> Bin | AF25: =IFERROR(IF(SEARCH("_TJ",D25)>0,"TJ",NA()),IFERROR(IF(SEARCH("_JB",D25)>0,"JB",NA()),"OLD")) -> OLD
